Workbook

Sheet ShipWatch Departure Berth
C3: Departure Berth Report
B5: Vessel IMO: | C5: 9489118
B6: Vessel Name: | C6: Navig8 Constellation
B7: Officers: | C7: Master | D7: CAPT. PAUL JAMES LLAMAS | N7: Chief Engineer | O7: ALBERTO DY
B8: Date and Time: | C8: Date (dd/mm/yyyy) | D8: 45492 | N8: Local Time (hh:mm) | O8: 0.47569444 | U8: UTC Offset (±hh:mm) | V8: +01:00
C9: UTC Date/Time | D9: 45492
B11: Position: | C11: Latitude | D11: 8 | E11: 0 | F11: 36 | J11: ' | K11: 11.6 | L11: " | M11: S | N11: Longitude | O11: 48 | P11: 0 | Q11: 59 | R11: ' | S11: 22.1 | T11: " | U11: E
B13: Current Port: | C13: LAKONIKOS GULF, GREECE
B14: ETD: | C14: Date (dd/mm/yyyy) | N14: Local Time (hh:mm) | U14: UTC Offset (±hh:mm)
C15: ETD UTC Date/Time | D15: =IF(OR(D14="",O14="",V14=""),"",INT(D14)+O14-((NUMBERVALUE(MID(V14,2,2))/24+(RIGHT(V14,2)/60/24)))*(IF(LEFT(V14,1)="+",1,-1)))
B16: On Berth Hours: | C16: 17.2 | D16: Hours
B17: Maneuvering Hours: | C17: 0 | D17: Hours | F17: Vessel Condition (BL/LD): | J17: Ballast
B18: Hours Since Last Report: | C18: =C16+C17 -> 17.2 | D18: Hours | F18: Draft Fore (m): | J18: 3.5 | K18: m
B19: Observed Distance (nm): | C19: 0 | D19: NM | F19: Draft Aft (m): | J19: 4.9 | K19: m
B20: ME Running Hours (Counter) | C20: 44257.38 | D20: Hours | F20: RPM (Counter) | J20: 62897104 | K20: RPM
B22: Total Cargo On Board m3: | C22: 5.4521 | D22: m3
B23: Total Cargo On Board: | C23: 1.4526 | D23: MT
B24: Total Cargo Loaded/Discharged: | C24: Loaded | D24: 254.3562 | E24: MT | H24: Discharged | J24: 2442.17 | K24: MT
B26: General Remarks: | C26: Testing@123
B30: Engine Hours | C30: ME | F30: AE | K30: Shaft Generator
F31: 1 | G31: 2 | H31: 3 | I31: 4
B32: Running Hours | C32: 7.7777 | F32: 17.2 | G32: 17.2 | H32: 14.5264 | I32: 11.2545 | K32: 12.54563
B34: Power (kW) | C34: 6.4584 | F34: 126 | G34: 126 | H34: 154 | I34: 165 | K34: 15.45874
B37: Bunkers | C37: HEAVY IFO 3.5% | F37: HEAVY LFO 0.5% | K37: MGO 0.5% | N37: LGO 0.1% | P37: LIGHT IFO 3.5% | R37: LIGHT LFO 0.5%
C38: RME - RMK (> 80 cSt) | F38: RME - RMK (> 80 cSt) | P38: RMA - RMD (< 80 cSt) | R38: RMA - RMD (< 80 cSt)
B39: Bunkers Supplied | C39: 2.5445 | F39: 21.4562 | K39: 1.544 | N39: 3.4564 | P39: 2.456 | R39: 7.453543
B41: Bunker Survey/De-Bunkering | C41: 2.8475 | F41: 6.452 | K41: 1 | N41: 5.642 | P41: 2.4564 | R41: 1.54685
B43: ROB | C43: 9.545 | F43: 9.45512 | K43: 6.54545 | N43: 296.22 | P43: 3.454 | R43: 8.4535
B45: Consumptions
B47: Main Engine: | C47: 5 | F47: 8 | K47: 1 | N47: 3 | P47: 8 | R47: 1
B49: Main Engine Total: | C49: =C47 -> 5 | F49: =F47 -> 8 | K49: =K47 -> 1 | N49: =N47 -> 3 | P49: =P47 -> 8 | R49: =R47 -> 1
B51: Standard A/E: | C51: 8 | F51: 6 | K51: 4 | N51: 1 | P51: 2 | R51: 8
B53: Cargo Cooling A/E: | C53: 5 | F53: 9 | K53: 1 | N53: 0 | P53: 8 | R53: 3
B55: Cargo Loading A/E: | C55: 5 | F55: 4 | K55: 2 | N55: 4 | P55: 7 | R55: 4
B57: Cargo Discharging A/E: | C57: 7 | F57: 3 | K57: 5 | N57: 3 | P57: 4 | R57: 3
B59: Ballast Water A/E: | C59: 5 | F59: 2 | K59: 4 | N59: 2 | P59: 7 | R59: 5
B61: Other A/E: | C61: 4 | F61: 2 | K61: 1 | N61: 4 | P61: 5 | R61: 4
B63: A/E Total: | C63: =C61+C59+C53+C51+C55+C57 -> 34 | F63: =F61+F59+F53+F51+F55+F57 -> 26 | K63: =K61+K59+K53+K51+K55+K57 -> 17 | N63: =N61+N59+N53+N51+N55+N57 -> 14 | P63: =P61+P59+P53+P51+P55+P57 -> 33 | R63: =R61+R59+R53+R51+R55+R57 -> 27
B65: Standard Boiler: | C65: 5 | F65: 6 | K65: 5 | N65: 0.3 | P65: 3 | R65: 56.645
B67: Cargo Cooling Boiler: | C67: 2 | F67: 4 | K67: 5 | N67: 3 | P67: 4 | R67: 2.5445
...

Sheet Validation
B1: UTC Offset
B2: -12:00
B3: -11:00
B4: -10:00
B5: -09:30
B6: -09:00
B7: -08:00
B8: -07:00
B9: -06:00
B10: -05:00
B11: -04:00
B12: -03:30
... B37: +14:00

Sheet Table
A1: Version | B1: CargoDischargingAE_IFO | C1: CargoDischargingAE_LFO | D1: CargoDischargingAE_MGO | E1: CargoDischargingAE_LGO | F1: CargoDischargingBoiler_IFO | G1: CargoDischargingBoiler_LFO | H1: CargoDischargingBoiler_MGO | I1: CargoDischargingBoiler_LGO | J1: CargoLoadingAE_IFO | K1: CargoLoadingAE_LFO | L1: CargoLoadingAE_MGO | M1: CargoLoadingAE_LGO | N1: CargoLoadingBoiler_IFO | O1: CargoLoadingBoiler_LFO | P1: CargoLoadingBoiler_MGO | Q1: CargoLoadingBoiler_LGO | R1: RemarksforOtherCons | S1: AETotalConsumption_LFO | T1: BallastWaterAE_LFO | U1: BallastWaterBoiler_LFO | V1: BoilerTotalConsumption_LFO | W1: CargoCoolingAE_LFO | X1: CargoCoolingBoiler_LFO | Y1: MainEngine_LFO | Z1: MainEngineTotal_LFO | AA1: OthrAE_LFO | AB1: OthrBoiler_LFO | AC1: ROB_LFO | AD1: StandardAE_LFO | AE1: StandardBoiler_LFO | AF1: TotalConsumption_LFO | AG1: AETotalConsumption_IFO | AH1: BallastWaterAE_IFO | AI1: BallastWaterBoiler_IFO | AJ1: BoilerTotalConsumption_IFO | AK1: CargoCoolingAE_IFO | AL1: CargoCoolingBoiler_IFO | AM1: MainEngine_IFO | AN1: MainEngineTotal_IFO | AO1: OtherAE_IFO | AP1: OtherBoiler_IFO | AQ1: ROB_IFO | AR1: StandardAE_IFO | AS1: StandardBoiler_IFO | AT1: TotalConsumption_IFO | AU1: AETotalConsumption_MGO | AV1: BallastWaterAE_MGO | AW1: BallastWaterBoiler_MGO | AX1: BoilerTotalConsumption_MGO | AY1: CargoCoolingAE_MGO | AZ1: CargoCoolingBoiler_MGO | BA1: MainEngine_MGO | BB1: MainEngineTotal_MGO | BC1: OtherAE_MGO | BD1: OtherBoiler_MGO | BE1: ROB_MGO | BF1: StandardAE_MGO | BG1: StandardBoiler_MGO | BH1: TotalConsumption_MGO | BI1: AETotalConsumption_LGO | BJ1: BallastWaterAE_LGO | BK1: BallastWaterBoiler_LGO | BL1: BoilerTotalConsumption_LGO | BM1: CargoCoolingAE_LGO | BN1: CargoCoolingBoiler_LGO | BO1: MainEngine_LGO | BP1: MainEngineTotal_LGO | BQ1: OtherAE_LGO | BR1: OtherBoiler_LGO | BS1: ROB_LGO | BT1: StandardAE_LGO | BU1: StandardBoiler_LGO | BV1: TotalConsumption_LGO | BW1: BunkersSuppliedIFO | BX1: BunkersSuppliedLFO | BY1: BunkersSuppliedMGO | BZ1: BunkersSuppliedLGO | CA1: BunkersSuppliedLIFO | CB1: BunkersSuppliedLLFO | CC1: BunkerSurveyDeBunkeringIFO | CD1: BunkerSurveyDeBunkeringLFO | CE1: BunkerSurveyDeBunkeringMGO | CF1: BunkerSurveyDeBunkeringLGO | CG1: BunkerSurveyDeBunkeringLIFO | CH1: BunkerSurveyDeBunkeringLLFO | CI1: DraftAftm | CJ1: DraftForem | CK1: GeneralRemarks | CL1: HoursSinceLastReport | CM1: ObservedDistancenm | CN1: MEPowerkW | CO1: MERunningHours | CP1: AE1RunningHours | CQ1: AE1PowerKW | CR1: AE2RunningHours | CS1: AE2PowerKW | CT1: AE3RunningHours | CU1: AE3PowerKW | CV1: AE4RunningHours | CW1: AE4PowerKW | CX1: ShaftGeneratorPower | CY1: ShaftGeneratorRunningHours | CZ1: VesselConditionBallastLaden | DA1: LatitudeDeg | DB1: LatitudeMin | DC1: LatitudeSec | DD1: LatitudeDir | DE1: LongitudeDeg | DF1: LongitudeMin | DG1: LongitudeSec | DH1: LongitudeDir | DI1: RPMCounter | DJ1: MERunningHoursCounter | DK1: CargoCoolingHours | DL1: LoadHours | DM1: DischargeHours | DN1: TotalCargoOnBoard | DO1: CargoLoaded | DP1: CargoDischarged | DQ1: ChiefEngineer | DR1: Master | DS1: UTCOffset | DT1: VesselIMO | DU1: VesselName | DV1: ReportType | DW1: CurrentPort | DX1: ETDUTCOffset | DY1: ManeuveringHours | DZ1: OnBerthHours | EA1: Date | EB1: Time | EC1: UTCTimestamp | ED1: ETDUTCTimestamp | EE1: ETDDate | EF1: ETDTime | EG1: AETotalConsumption_LIFO | EH1: BallastWaterAE_LIFO | EI1: BallastWaterBoiler_LIFO | EJ1: BoilerTotalConsumption_LIFO | EK1: CargoCoolingAE_LIFO | EL1: CargoCoolingBoiler_LIFO | EM1: MainEngine_LIFO | EN1: MainEngineTotal_LIFO | EO1: OtherAE_LIFO | EP1: OtherBoiler_LIFO | EQ1: CargoDischargingAE_LIFO | ER1: CargoDischargingBoiler_LIFO | ES1: CargoLoadingAE_LIFO | ET1: CargoLoadingBoiler_LIFO | EU1: ROB_LIFO | EV1: StandardAE_LIFO | EW1: StandardBoiler_LIFO | EX1: TotalConsumption_LIFO | EY1: AETotalConsumption_LLFO | EZ1: BallastWaterAE_LLFO | FA1: BallastWaterBoiler_LLFO | FB1: BoilerTotalConsumption_LLFO | FC1: CargoCoolingAE_LLFO | FD1: CargoCoolingBoiler_LLFO | FE1: MainEngine_LLFO | FF1: MainEngineTotal_LLFO | FG1: OtherAE_LLFO | FH1: OtherBoiler_LLFO | FI1: CargoDischargingAE_LLFO | FJ1: CargoDischargingBoiler_LLFO | FK1: CargoLoadingAE_LLFO | FL1: CargoLoadingBoiler_LLFO | FM1: ROB_LLFO | FN1: StandardAE_LLFO | FO1: StandardBoiler_LLFO | FP1: TotalConsumption_LLFO | FQ1: CargoCoolingEnergykWh | FR1: TotalCargoOnBoardM3
A2: LPG/DepartureBerth/V3 | B2: ='ShipWatch Departure Berth'!C57 -> 7 | C2: ='ShipWatch Departure Berth'!F57 -> 3 | D2: ='ShipWatch Departure Berth'!K57 -> 5 | E2: ='ShipWatch Departure Berth'!N57 -> 3 | F2: ='ShipWatch Departure Berth'!C71 -> 1 | G2: ='ShipWatch Departure Berth'!F71 -> 2 | H2: ='ShipWatch Departure Berth'!K71 -> 4 | I2: ='ShipWatch Departure Berth'!N71 -> 4 | J2: ='ShipWatch Departure Berth'!C55 -> 5 | K2: ='ShipWatch Departure Berth'!F55 -> 4 | L2: ='ShipWatch Departure Berth'!K55 -> 2 | M2: ='ShipWatch Departure Berth'!N55 -> 4 | N2: ='ShipWatch Departure Berth'!C69 -> 2 | O2: ='ShipWatch Departure Berth'!F69 -> 8 | P2: ='ShipWatch Departure Berth'!K69 -> 3 | Q2: ='ShipWatch Departure Berth'!N69 -> 5 | R2: =IF('ShipWatch Departure Berth'!C86="","",'ShipWatch Departure Berth'!C86) -> Testing@12345 | S2: ='ShipWatch Departure Berth'!F63 -> 26 | T2: ='ShipWatch Departure Berth'!F59 -> 2 | U2: ='ShipWatch Departure Berth'!F73 -> 1 | V2: ='ShipWatch Departure Berth'!F77 -> 25 | W2: ='ShipWatch Departure Berth'!F53 -> 9 | X2: ='ShipWatch Departure Berth'!F67 -> 4 | Y2: ='ShipWatch Departure Berth'!F47 -> 8 | Z2: ='ShipWatch Departure Berth'!F49 -> 8 | AA2: ='ShipWatch Departure Berth'!F61 -> 2 | AB2: ='ShipWatch Departure Berth'!F75 -> 4 | AC2: ='ShipWatch Departure Berth'!F43 -> 9.45512 | AD2: ='ShipWatch Departure Berth'!F51 -> 6 | AE2: ='ShipWatch Departure Berth'!F65 -> 6 | AF2: ='ShipWatch Departure Berth'!F79 -> 59 | AG2: ='ShipWatch Departure Berth'!C63 -> 34 | AH2: ='ShipWatch Departure Berth'!C59 -> 5 | AI2: ='ShipWatch Departure Berth'!C73 -> 3 | AJ2: ='ShipWatch Departure Berth'!C77 -> 20 | AK2: ='ShipWatch Departure Berth'!C53 -> 5 | AL2: ='ShipWatch Departure Berth'!C67 -> 2 | AM2: ='ShipWatch Departure Berth'!C47 -> 5 | AN2: ='ShipWatch Departure Berth'!C49 -> 5 | AO2: ='ShipWatch Departure Berth'!C61 -> 4 | AP2: ='ShipWatch Departure Berth'!C75 -> 7 | AQ2: ='ShipWatch Departure Berth'!C43 -> 9.545 | AR2: ='ShipWatch Departure Berth'!C51 -> 8 | AS2: ='ShipWatch Departure Berth'!C65 -> 5 | AT2: ='ShipWatch Departure Berth'!C79 -> 59 | AU2: ='ShipWatch Departure Berth'!K63 -> 17 | AV2: ='ShipWatch Departure Berth'!K59 -> 4 | AW2: ='ShipWatch Departure Berth'!K73 -> 2 | AX2: ='ShipWatch Departure Berth'!K77 -> 20 | AY2: ='ShipWatch Departure Berth'!K53 -> 1 | AZ2: ='ShipWatch Departure Berth'!K67 -> 5 | BA2: ='ShipWatch Departure Berth'!K47 -> 1 | BB2: ='ShipWatch Departure Berth'!K49 -> 1 | BC2: ='ShipWatch Departure Berth'!K61 -> 1 | BD2: ='ShipWatch Departure Berth'!K75 -> 1 | BE2: ='ShipWatch Departure Berth'!K43 -> 6.54545 | BF2: ='ShipWatch Departure Berth'!K51 -> 4 | BG2: ='ShipWatch Departure Berth'!K65 -> 5 | BH2: ='ShipWatch Departure Berth'!K79 -> 38 | BI2: ='ShipWatch Departure Berth'!N63 -> 14 | BJ2: ='ShipWatch Departure Berth'!N59 -> 2 | BK2: ='ShipWatch Departure Berth'!N73 -> 3 | BL2: ='ShipWatch Departure Berth'!N77 -> 22.3 | BM2: ='ShipWatch Departure Berth'!N53 -> 0 | BN2: ='ShipWatch Departure Berth'!N67 -> 3 | BO2: ='ShipWatch Departure Berth'!N47 -> 3 | BP2: ='ShipWatch Departure Berth'!N49 -> 3 | BQ2: ='ShipWatch Departure Berth'!N61 -> 4 | BR2: ='ShipWatch Departure Berth'!N75 -> 7 | BS2: ='ShipWatch Departure Berth'!N43 -> 296.22 | BT2: ='ShipWatch Departure Berth'!N51 -> 1 | BU2: ='ShipWatch Departure Berth'!N65 -> 0.3 | BV2: ='ShipWatch Departure Berth'!N79 -> 39.3 | BW2: ='ShipWatch Departure Berth'!C39 -> 2.5445 | BX2: ='ShipWatch Departure Berth'!F39 -> 21.4562 | BY2: ='ShipWatch Departure Berth'!K39 -> 1.544 | BZ2: ='ShipWatch Departure Berth'!N39 -> 3.4564 | CA2: ='ShipWatch Departure Berth'!P39 -> 2.456 | CB2: ='ShipWatch Departure Berth'!R39 -> 7.453543 | CC2: ='ShipWatch Departure Berth'!C41 -> 2.8475 | CD2: ='ShipWatch Departure Berth'!F41 -> 6.452 | CE2: ='ShipWatch Departure Berth'!K41 -> 1 | CF2: ='ShipWatch Departure Berth'!N41 -> 5.642 | CG2: ='ShipWatch Departure Berth'!P41 -> 2.4564 | CH2: ='ShipWatch Departure Berth'!R41 -> 1.54685 | CI2: =IF('ShipWatch Departure Berth'!J19="","",'ShipWatch Departure Berth'!J19) -> 4.9 | CJ2: =IF('ShipWatch Departure Berth'!J18="","",'ShipWatch Departure Berth'!J18) -> 3.5 | CK2: =IF('ShipWatch Departure Berth'!C26="","",'ShipWatch Departure Berth'!C26) -> Testing@123 | CL2: =IF('ShipWatch Departure Berth'!C18="","",'ShipWatch Departure Berth'!C18) -> 17.2 | CM2: =IF('ShipWatch Departure Berth'!C19="","",'ShipWatch Departure Berth'!C19) -> 0 | CN2: =IF('ShipWatch Departure Berth'!C34="","",'ShipWatch Departure Berth'!C34) -> 6.4584 | CO2: =IF('ShipWatch Departure Berth'!C32="","",'ShipWatch Departure Berth'!C32) -> 7.7777 | CP2: =IF('ShipWatch Departure Berth'!F32="","",'ShipWatch Departure Berth'!F32) -> 17.2 | CQ2: =IF('ShipWatch Departure Berth'!F34="","",'ShipWatch Departure Berth'!F34) -> 126 | CR2: =IF('ShipWatch Departure Berth'!G32="","",'ShipWatch Departure Berth'!G32) -> 17.2 | CS2: =IF('ShipWatch Departure Berth'!G34="","",'ShipWatch Departure Berth'!G34) -> 126 | CT2: =IF('ShipWatch Departure Berth'!H32="","",'ShipWatch Departure Berth'!H32) -> 14.5264 | CU2: =IF('ShipWatch Departure Berth'!H34="","",'ShipWatch Departure Berth'!H34) -> 154 | CV2: =IF('ShipWatch Departure Berth'!I32="","",'ShipWatch Departure Berth'!I32) -> 11.2545 | CW2: =IF('ShipWatch Departure Berth'!I34="","",'ShipWatch Departure Berth'!I34) -> 165 | CX2: =IF('ShipWatch Departure Berth'!K34="","",'ShipWatch Departure Berth'!K34) -> 15.45874 | CY2: =IF('ShipWatch Departure Berth'!K32="","",'ShipWatch Departure Berth'!K32) -> 12.54563 | CZ2: =IF('ShipWatch Departure Berth'!J17="","",'ShipWatch Departure Berth'!J17) -> Ballast | DA2: =IF('ShipWatch Departure Berth'!D11="","",'ShipWatch Departure Berth'!D11) -> 8 | DB2: =IF('ShipWatch Departure Berth'!F11="","",'ShipWatch Departure Berth'!F11) -> 36 | DC2: =IF('ShipWatch Departure Berth'!K11="","",'ShipWatch Departure Berth'!K11) -> 11.6 | DD2: =IF('ShipWatch Departure Berth'!M11="","",'ShipWatch Departure Berth'!M11) -> S | DE2: =IF('ShipWatch Departure Berth'!O11="","",'ShipWatch Departure Berth'!O11) -> 48 | DF2: =IF('ShipWatch Departure Berth'!Q11="","",'ShipWatch Departure Berth'!Q11) -> 59 | DG2: =IF('ShipWatch Departure Berth'!S11="","",'ShipWatch Departure Berth'!S11) -> 22.1 | DH2: =IF('ShipWatch Departure Berth'!U11="","",'ShipWatch Departure Berth'!U11) -> E | DI2: =IF('ShipWatch Departure Berth'!J20="","",'ShipWatch Departure Berth'!J20) -> 62897104 | DJ2: =IF('ShipWatch Departure Berth'!C20="","",'ShipWatch Departure Berth'!C20) -> 44257.38 | DK2: =IF('ShipWatch Departure Berth'!C83="","",'ShipWatch Departure Berth'!C83) -> 2.5464 | DL2: =IF('ShipWatch Departure Berth'!H83="","",'ShipWatch Departure Berth'!H83) -> 7.45454 | DM2: =IF('ShipWatch Departure Berth'!C84="","",'ShipWatch Departure Berth'!C84) -> 34.5754 | DN2: =IF('ShipWatch Departure Berth'!C23="","",'ShipWatch Departure Berth'!C23) -> 1.4526 | DO2: =IF('ShipWatch Departure Berth'!D24="","",'ShipWatch Departure Berth'!D24) -> 254.3562 | DP2: =IF('ShipWatch Departure Berth'!J24="","",'ShipWatch Departure Berth'!J24) -> 2442.17 | DQ2: =IF('ShipWatch Departure Berth'!O7="","",'ShipWatch Departure Berth'!O7) -> ALBERTO DY | DR2: =IF('ShipWatch Departure Berth'!D7="","",'ShipWatch Departure Berth'!D7) -> CAPT. PAUL JAMES LLAMAS | DS2: =IF('ShipWatch Departure Berth'!V8="","",'ShipWatch Departure Berth'!V8) -> +01:00 | DT2: =IF('ShipWatch Departure Berth'!C5="","",'ShipWatch Departure Berth'!C5) -> 9489118 | DU2: =IF('ShipWatch Departure Berth'!C6="","",'ShipWatch Departure Berth'!C6) -> Navig8 Constellation | DV2: ="In Port" -> In Port | DW2: =IF('ShipWatch Departure Berth'!C13="","",'ShipWatch Departure Berth'!C13) -> LAKONIKOS GULF, GREECE | DX2: =IF('ShipWatch Departure Berth'!V14="","",'ShipWatch Departure Berth'!V14) | DY2: =IF('ShipWatch Departure Berth'!C17="","",'ShipWatch Departure Berth'!C17) -> 0 | DZ2: =IF('ShipWatch Departure Berth'!C16="","",'ShipWatch Departure Berth'!C16) -> 17.2 | EA2: =IF('ShipWatch Departure Berth'!D8="","",'ShipWatch Departure Berth'!D8) -> 45492 | EB2: =IF('ShipWatch Departure Berth'!O8="","",'ShipWatch Departure Berth'!O8) -> 0.47569444 | EC2: =IF('ShipWatch Departure Berth'!D9="","",'ShipWatch Departure Berth'!D9) -> 45492 | ED2: =IF('ShipWatch Departure Berth'!D15="","",'ShipWatch Departure Berth'!D15) | EE2: =IF('ShipWatch Departure Berth'!D14="","",'ShipWatch Departure Berth'!D14) | EF2: =IF('ShipWatch Departure Berth'!O14="","",'ShipWatch Departure Berth'!O14) | EG2: ='ShipWatch Departure Berth'!P63 -> 33 | EH2: ='ShipWatch Departure Berth'!P59 -> 7 | EI2: ='ShipWatch Departure Berth'!P73 -> 0.255 | EJ2: ='ShipWatch Departure Berth'!P77 -> 17.709 | EK2: ='ShipWatch Departure Berth'!P53 -> 8 | EL2: ='ShipWatch Departure Berth'!P67 -> 4 | EM2: ='ShipWatch Departure Berth'!P47 -> 8 | EN2: ='ShipWatch Departure Berth'!P49 -> 8 | EO2: ='ShipWatch Departure Berth'!P61 -> 5 | EP2: ='ShipWatch Departure Berth'!P75 -> 4.454 | EQ2: ='ShipWatch Departure Berth'!P57 -> 4 | ER2: ='ShipWatch Departure Berth'!P71 -> 3 | ES2: ='ShipWatch Departure Berth'!P55 -> 7 | ET2: ='ShipWatch Departure Berth'!P69 -> 3 | EU2: ='ShipWatch Departure Berth'!P43 -> 3.454 | EV2: ='ShipWatch Departure Berth'!P51 -> 2 | EW2: ='ShipWatch Departure Berth'!P65 -> 3 | EX2: ='ShipWatch Departure Berth'!P79 -> 58.709 | EY2: ='ShipWatch Departure Berth'!R63 -> 27 | EZ2: ='ShipWatch Departure Berth'!R59 -> 5 | FA2: ='ShipWatch Departure Berth'!R71 -> 4.457 | FB2: ='ShipWatch Departure Berth'!R77 -> 74.1871 | FC2: ='ShipWatch Departure Berth'!R53 -> 3 | FD2: ='ShipWatch Departure Berth'!R67 -> 2.5445 | FE2: ='ShipWatch Departure Berth'!R47 -> 1 | FF2: ='ShipWatch Departure Berth'!R49 -> 1 | FG2: ='ShipWatch Departure Berth'!R61 -> 4 | FH2: ='ShipWatch Departure Berth'!R75 -> 3.4545 | FI2: ='ShipWatch Departure Berth'!R57 -> 3 | FJ2: ='ShipWatch Departure Berth'!R71 -> 4.457 | FK2: ='ShipWatch Departure Berth'!R55 -> 4 | FL2: ='ShipWatch Departure Berth'!R69 -> 6.544 | FM2: ='ShipWatch Departure Berth'!R43 -> 8.4535 | FN2: ='ShipWatch Departure Berth'!R51 -> 8 | FO2: ='ShipWatch Departure Berth'!R65 -> 56.645 | FP2: ='ShipWatch Departure Berth'!R79 -> 102.1871 | FQ2: ='ShipWatch Departure Berth'!C84 -> 34.5754 | FR2: =IF('ShipWatch Departure Berth'!C22="","",'ShipWatch Departure Berth'!C22) -> 5.4521
